<?xml version="1.0"?>
<robot xmlns:xacro="http://wiki.ros.org/xacro" name="sensor_axis">
  <xacro:property name="ptz_joint_effort_limit" value="10.0"/>
  <xacro:property name="ptz_joint_velocity_limit" value="1.0"/>
  <xacro:property name="ptz_joint_friction" value="0.1"/>
  <xacro:property name="ptz_joint_damping" value="0.1"/>
  <xacro:property name="ptz_mechanical_reduction" value="1.0"/>
  <xacro:property name="PI" value="3.14159265359"/>
  <xacro:macro name="sensor_accupoint_ap8" params="prefix parent *origin include_inertial:=^|true">
    
    <joint name="${prefix}_base_joint" type="fixed">
      <axis xyz="0 0 1"/>
      <xacro:insert_block name="origin"/>
      <parent link="${parent}"/>
      <child link="${prefix}_base_link"/>
    </joint>
    
    <link name="${prefix}_base_link">
      <xacro:if value="${include_inertial}">
        <inertial>
          <origin xyz="0.0 0.0 0.0" rpy="0 0 0"/>
          <mass value="0.1"/>
          <origin xyz="0 0 0" rpy="0 0 0"/>
          <inertia ixx="0.1" ixy="0" ixz="0" iyy="0.1" iyz="0" izz="0.1"/>
        </inertial>
      </xacro:if>
      <visual>
        <origin xyz="0.0 0.0 0.0" rpy="0 0 0"/>
        <geometry>
          <mesh filename="package://robotnik_sensors/meshes/accupoint_ap8_pt/accupoint_ap8_base.dae"/>
        </geometry>
      </visual>
      <collision>
        <origin xyz="0.0 0.0 0.0" rpy="0 0 0"/>
        <geometry>
          <mesh filename="package://robotnik_sensors/meshes/accupoint_ap8_pt/accupoint_ap8_base.stl"/>
        </geometry>
      </collision>
      
    </link>
    
    <joint name="${prefix}_pan_joint" type="revolute">
      <axis xyz="0 0 1"/>
      <origin xyz="0.0 0.0 0.0" rpy="0 0 0"/>
      <!-- check the displacement -->
      <parent link="${prefix}_base_link"/>
      <child link="${prefix}_pan_link"/>
      <limit effort="${ptz_joint_effort_limit}" velocity="${ptz_joint_velocity_limit}" lower="-3.1415" upper="3.1415"/>
      <joint_properties damping="${ptz_joint_damping}" friction="{ptz_joint_friction}"/>
    </joint>
    
    <link name="${prefix}_pan_link">
      <xacro:if value="${include_inertial}">
        <inertial>
          <mass value="0.1"/>
          <origin xyz="0 0 0" rpy="0 0 0"/>
          <inertia ixx="0.1" ixy="0" ixz="0" iyy="0.1" iyz="0" izz="0.1"/>
        </inertial>
      </xacro:if>
      <visual>
        <origin xyz="0.0 0.0 0.0" rpy="0 0 ${PI/2}"/>
        <geometry>
          <mesh filename="package://robotnik_sensors/meshes/accupoint_ap8_pt/accupoint_ap8_pan.dae"/>
        </geometry>
      </visual>
      <collision>
        <origin xyz="0.0 0.0 0.0" rpy="0 0 ${PI/2}"/>
        <geometry>
          <mesh filename="package://robotnik_sensors/meshes/accupoint_ap8_pt/accupoint_ap8_pan.stl"/>
        </geometry>
      </collision>
    </link>

    <transmission name="${prefix}_pan_trans">
      <type>transmission_interface/SimpleTransmission</type>
      <joint name="${prefix}_pan_joint">
        <hardwareInterface>hardware_interface/PositionJointInterface</hardwareInterface>
      </joint>
      <actuator name="${prefix}pan_motor">
        <hardwareInterface>hardware_interface/PositionJointInterface</hardwareInterface>
        <mechanicalReduction>${ptz_mechanical_reduction}</mechanicalReduction>
      </actuator>
    </transmission>
    
    <joint name="${prefix}_tilt_joint" type="revolute">
      <axis xyz="0 0 1"/>
      <origin xyz="0.0 0.00587 0.0815" rpy="${PI/2} 0.0 0.0"/>
      <parent link="${prefix}_pan_link"/>
      <child link="${prefix}_tilt_link"/>
      <limit effort="${ptz_joint_effort_limit}" velocity="${ptz_joint_velocity_limit}" lower="-1.5708" upper="1.5708"/>
      <joint_properties damping="${ptz_joint_damping}" friction="{ptz_joint_friction}"/>
    </joint>
    
    <link name="${prefix}_tilt_link">
      <xacro:if value="${include_inertial}">
        <inertial>
          <mass value="0.1"/>
          <origin xyz="0 0 0" rpy="0 0 0"/>
          <inertia ixx="0.1" ixy="0" ixz="0" iyy="0.1" iyz="0" izz="0.1"/>
        </inertial>
      </xacro:if>
      <visual>
        <origin xyz="0.0 0.0 0.0" rpy="-${PI/2} 0 0"/>
        <geometry>
          <mesh filename="package://robotnik_sensors/meshes/accupoint_ap8_pt/accupoint_ap8_tilt.dae"/>
        </geometry>
      </visual>
      <collision>
        <origin xyz="0.0 0.0 0.0" rpy="-${PI/2} 0 0"/>
        <geometry>
          <mesh filename="package://robotnik_sensors/meshes/accupoint_ap8_pt/accupoint_ap8_tilt.stl"/>
        </geometry>
      </collision>
    </link>
    
    <transmission name="${prefix}_tilt_trans">
      <type>transmission_interface/SimpleTransmission</type>
      <joint name="${prefix}_tilt_joint">
        <hardwareInterface>hardware_interface/PositionJointInterface</hardwareInterface>
      </joint>
      <actuator name="${prefix}tilt_motor">
        <hardwareInterface>hardware_interface/PositionJointInterface</hardwareInterface>
        <mechanicalReduction>${ptz_mechanical_reduction}</mechanicalReduction>
      </actuator>
    </transmission>
    
    <joint name="${prefix}_top_joint" type="fixed">
      <axis xyz="0 0 1"/>
      <origin xyz="0.0 0.068 0.00587" rpy="-${PI/2} 0.0 0.0"/>
      <parent link="${prefix}_tilt_link"/>
      <child link="${prefix}_top_link"/>
    </joint>
    
    <link name="${prefix}_top_link">
      <xacro:if value="${include_inertial}">
        <inertial>
          <mass value="0.1"/>
          <origin xyz="0 0 0" rpy="0 0 0"/>
          <inertia ixx="0.1" ixy="0" ixz="0" iyy="0.1" iyz="0" izz="0.1"/>
        </inertial>
      </xacro:if>
    </link>

  </xacro:macro>

</robot>
